Workbook

Sheet Main
B2: TMs & HMs | C2: Move Tutors | D2: Overworld Items
B3: Mega Stones | C3: Check the different tabs at the bottom to navigate through categories, or click/tap the links in the boxes around to access these tabs. | D3: Z-Crystals
B4: Shops | C4: Care Packages | D4: Other Useful Items

Sheet TMs & HMs
A1: TM | B1: MOVE | E1: LOCATION | L1: HM | M1: MOVE | P1: LOCATION
A2: 001 | B2: =Source!$D$7 | C2: Close Combat | D2: =Source!$B$2 | E2: Cerulean Cave, 2F, in the south east part of the floor. | L2: 001 | M2: =Source!$D$18 | N2: Cut | O2: =Source!$B$2 | P2: S.S. Anne, from the Captain in his room.
A3: 002 | B3: =Source!$D$4 | C3: Dragon Claw | D3: =Source!$B$3 | E3: Route 14, in the small patch of grass above the Bikers. | L3: 002 | M3: =Source!$D$9 | N3: Fly | O3: =Source!$B$3 | P3: Route 16, from a girl in the house in the top left corner of the Route.
A4: 003 | B4: =Source!$D$19 | C4: Flip Turn | D4: =Source!$B$2 | E4: Cerulean City's gym, from Misty after defeating her. | L4: 003 | M4: =Source!$D$19 | N4: Surf | O4: =Source!$B$2 | P4: Safari Zone Area 3, from the guy inside the northern Rest House.
A5: 004 | B5: =Source!$D$11 | C5: Seed Bomb | D5: =Source!$B$3 | E5: Route 12, in the grassy area below Fisherman's house. | L5: 004 | M5: =Source!$D$14 | N5: Strength | O5: =Source!$B$3 | P5: Fuchsia City, from Warden in the south-eastern house after giving him Gold Teeth.
A6: 005 | B6: =Source!$D$14 | C6: Roar | D6: =Source!$B$2 | E6: Route 4, after Mt. Moon, right of the two Black Belts, in between the multiple ledges. | L6: 005 | M6: =Source!$D$5 | N6: Flash | O6: =Source!$B$2 | P6: Route 2, from Professor Oak's Scientist in the eastern gate.
A7: 006 | B7: =Source!$D$15 | C7: Toxic | D7: =Source!$B$3 | E7: Celadon City's Game Corner for $17 500. | L7: 006 | M7: =Source!$D$7 | N7: Rock Smash | O7: =Source!$B$3 | P7: Fuchsia City, from Brendan after defeating him in front of Safari Zone's entrance.
A8: 007 | B8: =Source!$D$8 | C8: Heat Wave | D8: =Source!$B$2 | E8: Cinnabar Island's Pokémon Mansion 3F. | L8: 007 | M8: =Source!$D$19 | N8: Waterfall | O8: =Source!$B$2 | P8: (POST-GAME) From an old man on Island One, in the Ember Spa.
A9: 008 | B9: =Source!$D$16 | C9: Zen Headbutt | D9: =Source!$B$3 | E9: Saffron City's Silph Co. 7F, in the middle-right room. (Keycard required) | L9: 008 | M9: =Source!$D$14 | N9: Rock Climb | O9: =Source!$B$3 | P9: CANNOT BE FOUND.
A10: 009 | B10: =Source!$D$11 | C10: Bullet Seed | D10: =Source!$B$2 | E10: Mt. Moon 1F, west from the entrance.
A11: 010 | B11: =Source!$D$14 | C11: Hidden Power | D11: =Source!$B$3 | E11: Saffron City's Silph Co. 1F, on the upper right corner of the room behind a plant.
A12: 011 | B12: =Source!$D$5 | C12: Supercell Slam | D12: =Source!$B$2 | E12: Indigo Plateau, before entering the building, from soupercell after defeating him.
A13: 012 | B13: =Source!$D$3 | C13: Taunt | D13: =Source!$B$3 | E13: Celadon City's Rocket Hideout B2F inside the warp maze.
F14: (HARDCORE) Unavailable.
A15: 013 | B15: =Source!$D$13 | C15: Ice Beam | D15: =Source!$B$2 | E15: Celadon City's Game Corner for $30 000.
A16: 014 | B16: =Source!$D$13 | C16: Blizzard | D16: =Source!$B$3 | E16: Cinnabar Island's Pokémon Mansion B1F.
A17: 015 | B17: =Source!$D$5 | C17: Electroweb | D17: =Source!$B$2 | E17: Viridian Forest, follow the accessible path around the forest's end without rock break.
A18: 016 | B18: =Source!$D$16 | C18: Light Screen | D18: =Source!$B$3 | E18: Celadon City's Game Corner for $17 500.
A19: 017 | B19: =Source!$D$14 | C19: Protect | D19: =Source!$B$2 | E19: Celadon City's Game Corner for $15 000.
F20: (HARDCORE) Unavailable.
A21: 018 | B21: =Source!$D$19 | C21: Hydro Pump | D21: =Source!$B$3 | E21: Route 15, above the ledge near the Raid Den.
A22: 019 | B22: =Source!$D$11 | C22: Giga Drain | D22: =Source!$B$2 | E22: Celadon City's gym, from Erika after defeating her.
A23: 020 | B23: =Source!$D$14 | C23: Hyper Voice | D23: =Source!$B$3 | E23: Celadon City's Game Corner for $15 000.
A24: 021 | B24: =Source!$D$13 | C24: Icy Wind | D24: =Source!$B$2 | E24: Cerulean City's Pokémart for $5000.
A25: 022 | B25: =Source!$D$14 | C25: Weather Ball | D25: =Source!$B$3 | E25: Cinnabar Island's Pokémon Mansion B1F.
A26: 023 | B26: =Source!$D$18 | C26: Iron Head | D26: =Source!$B$2 | E26: Rock Tunnel 1F, from Lavender Town's side.
A27: 024 | B27: =Source!$D$5 | C27: Thunderbolt | D27: =Source!$B$3 | E27: Celadon City's Game Corner for $30 000.
A28: 025 | B28: =Source!$D$5 | C28: Thunder | D28: =Source!$B$2 | E28: Power Plant, south east corner.
A29: 026 | B29: =Source!$D$12 | C29: Earthquake | D29: =Source!$B$3 | E29: Saffron City, from the Dumbass Mudkip Kid after defeating him for the first time.
A30: 027 | B30: =Source!$D$14 | C30: Return | D30: =Source!$B$2 | E30: Route 12, from a Lass in the northern gate upstairs.
A31: 028 | B31: =Source!$D$12 | C31: Dig | D31: =Source!$B$3 | E31: Cerulean City, from Team Rocket Grunt.
A32: 029 | B32: =Source!$D$16 | C32: Psychic | D32: =Source!$B$2 | E32: Saffron City, in Mr. Psychic's house in the south east.
A33: 030 | B33: =Source!$D$10 | C33: Shadow Ball | D33: =Source!$B$3 | E33: Lavender Town, from Morty after defeating him in Fuji's house.
A34: 031 | B34: =Source!$D$7 | C34: Brick Break | D34: =Source!$B$2 | E34: S.S. Anne, 1F, second room starting from the left.
A35: 032 | B35: =Source!$D$7 | C35: Aura Sphere | D35: =Source!$B$3 | E35: Safari Zone - Western Area.
A36: 033 | B36: =Source!$D$16 | C36: Reflect | D36: =Source!$B$2 | E36: Celadon City's Game Corner for $15 000.
A37: 034 | B37: =Source!$D$16 | C37: Teleport | D37: =Source!$B$3 | E37: Route 3, in the large grassy patch with a Lass around.
A38: 035 | B38: =Source!$D$8 | C38: Flamethrower | D38: =Source!$B$2 | E38: Celadon City's Game Corner for $30 000.
A39: 036 | B39: =Source!$D$15 | C39: Sludge Bomb | D39: =Source!$B$3 | E39: Fuchsia City's gym, from Koga after defeating him.
A40: 037 | B40: =Source!$D$12 | C40: High Horsepower | D40: =Source!$B$2 | E40: Victory Road 2F, in the central-south part of the floor, below the heightened platform.
...

Sheet Move Tutors
A1: LOCATION | C1: CLASS / NAME | F1: MOVE(S) | L1: COST
A3: Moves highlighted in red aren't learnable on Restricted/Hardcore Mode.
A4: Locations/Move Tutors highlighted in red will disappear on Restricted/Hardcore Mode.
A7: Viridian Forest | C7: Bug Catcher | D7: =Source!$V$2
H9: Bug Bite | M9: =Source!$AT$44 | N9: 1 Oran Berry
A14: Cerulean City House next to Nugget Bridge | C14: Old Man | D14: =Source!$V$3
H16: Fire Fang | M16: =Source!$B$8 | N16: 1500
H17: Ice Fang
H19: Thunder Fang
A24: Vermilion City's Fanclub | C24: Tamer | D24: =Source!$V$4
H26: Flame Charge | M26: =Source!$B$8 | N26: 2500
H27: Trailblaze
H29: Power-Up Punch
H30: Charge Beam
H31: Work Up
H32: Hone Claws
A37: Pewter City's Museum (Requires Cut HM) | C37: Scientist | D37: =Source!$V$17
H39: Rock Polish | M39: =Source!$B$8 | N39: 2500
A44: Saffron City House left of Silph Co. | C44: Ace Trainer | D44: =Source!$V$5
H46: Drill Run | M46: =Source!$B$8 | N46: 7500
H47: Blaze Kick
H49: Pain Split
H50: Hex
H51: Mystical Fire
H52: Leaf Blade
H53: Power Gem
H54: Rock Blast
H55: Pin Missile
H56: Icicle Spear
H57: Tail Slap
H58: Body Slam
H59: Foul Play
... H62: Psychic Fangs
A67: Fuchsia City's Eastern Gate | C67: Super Nerd | D67: =Source!$V$6
H69: Swords Dance | M69: =Source!$B$8 | N69: 0
H70: Nasty Plot
H72: Bulk Up
H73: Calm Mind
H74: Meteor Beam
H75: Iron Defense
...

Sheet Overworld Items
B1: ITEM | F1: LOCATION
B2: Pallet Town
A3: =Source!$B$6 | B3: =Source!$AB$39 | C3: =Source!$B$7 | D3: Potion [x1] | F3: Computer in player's house.
A4: =Source!$B$6 | B4: =IMAGE("https://i.ibb.co/ZKvLNwv/4305432.png",4,24,24) | C4: =Source!$B$7 | D4: Time Changer | F4: At Oak's Lab, left Aide rewards correct quiz answers.
A5: =Source!$B$6 | B5: =Source!$AQ$146 | C5: =Source!$B$7 | D5: PokéDex | F5: From Professor Oak after bringing him the Parcel from Viridian City's Poké Mart.
A6: =Source!$B$6 | B6: =Source!$Y$30 | C6: =Source!$B$7 | D6: Poké Ball [x10] | F6: From Professor Oak after bringing him the Parcel from Viridian City's Poké Mart.
A7: =Source!$B$6 | B7: =IMAGE("https://i.ibb.co/ZBB5v1F/map.png",4,28,28) | C7: =Source!$B$7 | D7: Town Map | F7: From Daisy in Rival's house after getting PokéDex from Oak.
A8: =Source!$B$6 | B8: =Source!$S$7 | C8: =Source!$B$7 | D8: Eevium Z | F8: (POST-GAME) From Professor Oak after both battles. (Requires Z-Ring)
B12: Route 1
A13: =Source!$B$6 | B13: =Source!$AB$39 | C13: =Source!$B$7 | D13: Potion [x1] | F13: From the guy below the trees by the first ledge.
B17: Viridian City
A18: =Source!$B$6 | B18: =Source!$AE$25 | C18: =Source!$B$7 | D18: Repel [x1] | F18: In the narrow path on the north western side, behind a cut tree.
A19: =Source!$B$6 | B19: =Source!$AQ$138 | C19: =Source!$B$7 | D19: Oak's Parcel | F19: In the Poké Mart, given to you by the clerk.
A20: =Source!$B$6 | B20: =Source!$AN$104 | C20: =Source!$B$7 | D20: Wise Glasses | F20: From the girl in the trainers school.
A21: =Source!$B$6 | B21: =Source!$AQ$133 | C21: =Source!$B$7 | D21: Old Rod | F21: From a fisherman near a pond in the south west part of the city.
A22: =Source!$B$6 | B22: =Source!$AQ$205 | C22: =Source!$B$7 | D22: Teachy TV | F22: From the old man north of the city after receiving PokéDex from Oak.
A23: =Source!$B$6 | B23: =IMAGE("https://i.ibb.co/dQfV8w5/8145721.png",4,26,26) | C23: =Source!$B$7 | D23: Poké Vial | F23: From the Teacher in Trainers School after solving a puzzle battle.
A24: =Source!$B$6 | B24: =Source!$D$13 | C24: =Source!$B$7 | D24: TM 120 - Ice Spinner | F24: At the other side of the small pond. (Surf HM required)
A25: =Source!$B$6 | B25: =Source!$D$4 | C25: =Source!$B$7 | D25: TM 119 - Draco Meteor | F25: Viridian City's gym, from Clair after defeating her.
A26: =Source!$B$6 | B26: =Source!$D$4 | C26: =Source!$B$7 | D26: TM 072 - Draco Barrage | F26: (POST-GAME) From Clair after a rematch battle.
B30: Route 22
A31: =Source!$B$6 | B31: =Source!$P$42 | C31: =Source!$B$7 | D31: Scizorite | F31: In the middle of the Route in between the pond and a ledge. (Surf HM required)
B35: Route 2
A36: =Source!$B$6 | B36: =IMAGE("https://i.ibb.co/jJY5ScX/illustration-rare.png",4,26,26) | C36: =Source!$B$7 | D36: DexNav | F36: From Prof. Oak's Scientist upon entering the route.
A37: =Source!$B$6 | B37: =Source!$AB$2 | C37: =Source!$B$7 | D37: Ability Pill [x2] | F37: (HARDCORE) From Prof. Oak's Scientist upon entering the route.
A38: =Source!$B$6 | B38: =Source!$AT$44 | C38: =Source!$B$7 | D38: Oran Berry [x10] | F38: From Prof. Oak's Scientist upon entering the route.
A39: =Source!$B$6 | B39: =Source!$D$5 | C39: =Source!$B$7 | D39: HM 05 - Flash | F39: From Professor Oak's Aide in the south-eastern gate. (accessed later from Viridian City or Cut HM required)
A40: =Source!$B$6 | B40: =Source!$D$8 | C40: =Source!$B$7 | D40: TM 057 - Temper Flare | F40: Eastern side to the south. (Cut HM required)
A41: =Source!$B$6 | B41: =Source!$P$20 | C41: =Source!$B$7 | D41: Orbeetlite | F41: Above Diglett's Cave. (Rock Smash HM required)
B45: Viridian Forest
A46: =Source!$B$6 | B46: =Source!$AB$3 | C46: =Source!$B$7 | D46: Antidote [x1] | F46: Hidden just north of the western entrance.
A47: =Source!$B$6 | B47: =Source!$AB$39 | D47: Potion [x1] | F47: In the bottom right corner of the forest.
A48: =Source!$B$6 | B48: =Source!$AB$3 | C48: =Source!$B$7 | D48: Antidote [x1] | F48: In the top right area, near a Bug Catcher and a sign post.
A49: =Source!$B$6 | B49: =Source!$AB$39 | D49: Potion [x1] | F49: In the east part near a Bug Catcher, a bit further than where Brendan was.
A50: =Source!$B$6 | B50: =Source!$AB$39 | D50: Potion [x1] | F50: Hidden in grass near northern exit, where last Bug Catcher is looking.
A51: =Source!$B$6 | B51: =Source!$AQ$60 | C51: =Source!$B$7 | D51: Exp. Share | F51: From Brendan, after defeating him in front of the southern gate.
A52: =Source!$B$6 | B52: =Source!$AQ$178 | C52: =Source!$B$7 | D52: Stat Scanner | F52: From Brendan, after defeating him in front of the southern gate.
A53: =Source!$B$6 | B53: =IMAGE("https://i.ibb.co/7XCZGBH/spray1.png",4,18,24) | C53: =Source!$B$7 | D53: Infinite Repel | F53: From Lass Anne, after defeating her.
A54: =Source!$B$6 | B54: =Source!$D$5 | C54: =Source!$B$7 | D54: TM 015 - Electroweb | F54: Follow the small path at the end of the forest.
A55: =Source!$B$6 | B55: =Source!$D$2 | C55: =Source!$B$7 | D55: TM 081 - X-Scissor | F55: Follow the small path at the end of the forest. (Rock Smash HM required)
...

Sheet Mega Stones
B2: =IMAGE("https://i.ibb.co/FK6YJbz/g-Front-Sprite869-Venusaur-Mega.png",3) | E2: =Source!$P$48 | F2: Venusaurite | S2: =IMAGE("https://i.ibb.co/f9gmcxh/download.png",3) | V2: =Source!$P$15 | W2: Charizardite X
E3: Upstairs in northern gate on Route 16, from Scientist upon showing Venusaur. | V3: (Swapped with Charizardite Y in Hardcore) Upstairs in northern gate on Route 16, from Scientist after showing Charizard.
B6: =IMAGE("https://i.ibb.co/DkYJgnR/blastoise.png",3) | E6: =Source!$P$12 | F6: Blastoisinite | S6: =IMAGE("https://i.ibb.co/g4BjG2v/sceprtile.png",3) | V6: =Source!$P$41 | W6: Sceptilite
E7: Upstairs in northern gate on Route 16, from Scientist upon showing Blastoise. | V7: From Brendan after defeating him on Route 23.
B10: =IMAGE("https://i.ibb.co/wpLmPFY/blaziken.png",3) | E10: =Source!$P$13 | F10: Blazikenite | S10: =IMAGE("https://i.ibb.co/TPqqm1z/swamp.png",3) | V10: =Source!$P$46 | W10: Swampertite
E11: From May after defeating her on Cinnabar Island, in front of the Pokémon Mansion. | V11: From the Dumbass Mudkip Kid in Saffron City, after defeating him, then talking to him with a Swampert follower.
B14: =IMAGE("https://i.ibb.co/w4nctRn/luc.png",3) | E14: =Source!$P$30 | F14: Lucarionite | S14: =IMAGE("https://i.ibb.co/k4YtLRD/ala.png",3) | V14: =Source!$P$6 | W14: Alakazite
E15: In Celadon City, from the guy close to the Pokémon Center having a Lucario if you have a Lucario follower. (Soul Badge needed) | V15: Celadon City's Department Store, from a little girl on the rooftop.
B18: =IMAGE("https://i.ibb.co/HY4ZySf/sabl.png",3) | E18: =Source!$P$39 | F18: Sablenite | S18: =IMAGE("https://i.ibb.co/bRjYJgy/kang.png",3) | V18: =Source!$P$26 | W18: Kangaskhanite
E19: Lavender Town's Pokémon Tower in the 3rd floor, north side of the room. | V19: Saffron City's Silph Co. 7th floor, in the bottom left part of the floor, near a Scientist.
B22: =IMAGE("https://i.ibb.co/sVDsGqg/aud.png",3) | E22: =Source!$P$9 | F22: Audinite | S22: =IMAGE("https://i.ibb.co/Kw6WmQD/garb.png",3) | V22: =Source!$P$39 | W22: Garbodorite
E23: Saffron City's Silph Co. 6th floor, at the south west part of the floor, near a Scientist. | V23: Saffron City's Silph Co. 4th floor, in the far western room, Keycard is required to enter.
B26: =IMAGE("https://i.ibb.co/TMV2HZ0/gard.png",3) | E26: =Source!$P$20 | F26: Gardevoirite | S26: =IMAGE("https://i.ibb.co/YXmG77B/abs.png",3) | V26: =Source!$P$3 | W26: Absolite
E27: (Swapped with Cameruptite in Hardcore) From Sabrina after defeating her and showing a Pokémon with 31 IVs in all stats. (or a shiny in MGM/Hardcore) | V27: Route 17, on the south side near a sign post between two ponds.
B30: =IMAGE("https://i.ibb.co/G73DtfR/kingler.png",3) | E30: =Source!$P$12 | F30: Kinglerite | S30: =IMAGE("https://i.ibb.co/zm5gYV5/alt.png",3) | V30: =Source!$P$7 | W30: Altarianite
E31: Route 21, on an islet. | V31: Route 18, near the grass.
B34: =IMAGE("https://i.ibb.co/TwvqB5P/dred.png",3) | E34: =Source!$P$2 | F34: Drednawite | S34: =IMAGE("https://i.ibb.co/P1c6JsD/shark.png",3) | V34: =Source!$P$43 | W34: Sharpedonite
E35: Route 19, on a small islet on the south side of the Route. (Surf HM required) | V35: Route 12, from the Fisherman in a house if you talk to him with a Sharpedo follower.
B38: =IMAGE("https://i.ibb.co/4Wq7XxD/tox.png",3) | E38: =Source!$P$10 | F38: Toxtricitite | S38: =IMAGE("https://i.ibb.co/2KyJ934/hera.png",3) | V38: =Source!$P$24 | W38: Heracronite
E39: From Koga after defeating him and showing him a Pokémon with at least 150 EVs in Spe. (or 125 Base Spe in MGM/Hardcore) | V39: Safari Zone Eastern Area.
B42: =IMAGE("https://i.ibb.co/DbZDM6h/lop.png",3) | E42: =Source!$P$29 | F42: Lopunnite | S42: =IMAGE("https://i.ibb.co/BccyVBR/pidg.png",3) | V42: =Source!$P$37 | W42: Pidgeotite
E43: Safari Zone Western Area, at the south. | V43: Safari Zone North Area, up north.
B46: =IMAGE("https://i.ibb.co/LZb7z65/bee.png",3) | E46: =Source!$P$11 | F46: Beedrillite | S46: =IMAGE("https://i.ibb.co/23wG4BH/glal.png",3) | V46: =Source!$P$22 | W46: Glalitite
E47: Safari Zone North Area, in the eastern part of the area. | V47: Route 20, from Pryce after defeating him.
B50: =IMAGE("https://i.ibb.co/jV5XcKc/obama.png",3) | E50: =Source!$P$2 | F50: Abomasite | S50: =IMAGE("https://i.ibb.co/r5vJmQC/lapras.png",3) | V50: =Source!$P$46 | W50: Laprasite
E51: Seafoam Islands B2F, southern part of the floor. | V51: Seafoam Islands B2F, north eastern part of the floor.
B54: =IMAGE("https://i.ibb.co/9hfp7Wf/medi.png",3) | E54: =Source!$P$33 | F54: Medichamite | S54: =IMAGE("https://i.ibb.co/fvP0STH/agg.png",3) | V54: =Source!$P$5 | W54: Aggronite
E55: Route 20 (Cinnabar Island side), on a small islet below a stationary female Swimmer. | V55: In the Pokémon Lab, from Jasmine after defeating her.
B58: =IMAGE("https://i.ibb.co/1LkZSWk/megalati.png",3) | E58: =Source!$P$28 | F58: Latiosite | S58: =IMAGE("https://i.ibb.co/K9Nzz6n/megalatias.png",3) | V58: =Source!$P$27 | W58: Latiasite
E59: In Pokémon Lab's rightmost room, from Scientist at left table when showing Latios or Latias. | V59: In Pokémon Lab's rightmost room, from Scientist at left table when showing Latias or Latios.
B62: =IMAGE("https://i.ibb.co/rGv4dSm/steel.png",3) | E62: =Source!$P$45 | F62: Steelixite | S62: =IMAGE("https://i.ibb.co/Wfh9CD6/camel.png",3) | V62: =Source!$P$14 | W62: Cameruptite
E63: From Jasmine after defeating her and showing her a Pokémon with 150 EVs in Def. (125 Base Def in MGM/Hardcore) | V63: (Swapped with Gardevoirite in Hardcore) Cinnabar Island's Pokémon Mansion 1F, accessed by falling through the hole on 3F.
B66: =IMAGE("https://i.ibb.co/tZVP08g/zardy.png",3) | E66: =Source!$P$16 | F66: Charizardite Y | S66: =IMAGE("https://i.ibb.co/3yD63s1/ttar.png",3) | V66: =Source!$P$47 | W66: Tyranitarite
E67: (Swapped with Charizardite X in Hardcore) From Blaine after defeating him and showing a Pokémon with 150 EVs in SpA. (125 Base SpA in MGM/Hardcore) | V67: Route 24, on a small islet.
B70: =IMAGE("https://i.ibb.co/nk5Bdjb/maw.png",3) | E70: =Source!$P$32 | F70: Mawilite | S70: =IMAGE("https://i.ibb.co/4RvtLyz/doom.png",3) | V70: =Source!$P$25 | W70: Houndoominite
E71: Cerulean Cave 1F, from Ariana after defeating her in battle. | V71: Cerulean Cave 1F, from Archer after defeating him in battle.
B74: =IMAGE("https://i.ibb.co/KX7J4x5/y.png",3) | E74: =Source!$P$36 | F74: Mewtwonite Y | S74: =IMAGE("https://i.ibb.co/5v2b8qT/pinsir.png",3) | V74: =Source!$P$38 | W74: Pinsirite
E75: From Giovanni after defeating him in Cerulean Cave. | V75: Route 6, south west of the pond.
B78: =IMAGE("https://i.ibb.co/cJdKLq7/amph.png",3) | E78: =Source!$P$8 | F78: Ampharosite | S78: =IMAGE("https://i.ibb.co/RB5rpkK/machamp.png",3) | V78: =Source!$P$5 | W78: Machampite
E79: Power Plant, in the north east corner. | V79: Power Plant, from Dumbass Jojo Fan after defeating him.
...

Sheet Z-Crystals
B1: Z-CRYSTAL | F1: LOCATION
A3: =Source!$B$6 | B3: =Source!$S$3 | C3: =Source!$B$7 | D3: Bugium | F3: One Island, Kindle Road, from Bugsy after defeating him in a rematch.
A4: =Source!$B$6 | B4: =Source!$S$9 | C4: =Source!$B$7 | D4: Fairium | F4: One Island, Mt. Ember, northeast of the mountain.
A5: =Source!$B$6 | B5: =Source!$S$10 | C5: =Source!$B$7 | D5: Fightinium | F5: One Island, from Dumbass Jojo Fan after defeating him in rematch.
A6: =Source!$B$6 | B6: =Source!$S$12 | C6: =Source!$B$7 | D6: Flyinium | F6: Rock Tunnel area near the Power Plant.
A7: =Source!$B$6 | B7: =Source!$S$13 | C7: =Source!$B$7 | D7: Ghostium | F7: From Morty in the Pokémon Tower, post-trial defeat at the top.
A8: =Source!$B$6 | B8: =Source!$S$15 | C8: =Source!$B$7 | D8: Groundium | F8: Three Island Port, in the tunnel, from the digger.
A9: =Source!$B$6 | B9: =Source!$S$16 | C9: =Source!$B$7 | D9: Icium | F9: Seafoam Island secret area, from Pryce after defeating him in a rematch.
A10: =Source!$B$6 | B10: =Source!$S$24 | C10: =Source!$B$7 | D10: Normalium | F10: Two Island, near Joyful Game Corner, from Whitney post-rematch victory.
A11: =Source!$B$6 | B11: =Source!$S$29 | C11: =Source!$B$7 | D11: Psychium | F11: Three Island, Berry Forest, from Lostelle after defeating Mew.
A12: =Source!$B$6 | B12: =Source!$S$33 | C12: =Source!$B$7 | D12: Steelium | F12: Three Island, from a guy outside after defeating the Bikers.
A13: =Source!$B$6 | B13: =Source!$S$36 | C13: =Source!$B$7 | D13: Waterium | F13: Saffron City, from Gian (Mudkip Fan) after defeating him in a rematch.
A14: =Source!$B$6 | B14: =Source!$S$7 | C14: =Source!$B$7 | D14: Eevium | F14: Pallet Town, Oak's Lab, from Prof. Oak after a battle.
A15: =Source!$B$6 | B15: =Source!$S$21 | C15: =Source!$B$7 | D15: Marshadium | F15: In the Pokémon Tower, Dropped by Marshadow after top tower battle.
A16: =Source!$B$6 | B16: =Source!$S$22 | C16: =Source!$B$7 | D16: Mewium | F16: Berry Forest, from Gatekeeper Owen after the hidden Mew event's battle.
A17: =Source!$B$6 | B17: =Source!$S$23 | C17: =Source!$B$7 | D17: Mimikium | F17: Pokémon Tower, south of the Gengar puzzle room at the top of the Tower.
A18: =Source!$B$6 | B18: =Source!$S$34 | C18: =Source!$B$7 | D18: Tapunium | F18: One Island's Pokémon Center, from the Battle Simulator BP Exchange. (3 BP)
A19: =Source!$B$6 | B19: =Source!$S$31 | C19: =Source!$B$7 | D19: Snorlium | F19: One Island's Pokémon Center, from the Battle Simulator BP Exchange. (3 BP)
A20: =Source!$B$6 | B20: =Source!$S$25 | C20: =Source!$B$7 | D20: Pikanium | F20: One Island's Pokémon Center, from the Battle Simulator BP Exchange. (3 BP)
A21: =Source!$B$6 | B21: =Source!$S$26 | C21: =Source!$B$7 | D21: Pikashunium | F21: One Island's Pokémon Center, from the Battle Simulator BP Exchange. (5 BP)
A22: =Source!$B$6 | B22: =Source!$S$2 | C22: =Source!$B$7 | D22: Aloraichium | F22: One Island's Pokémon Center, from the Battle Simulator BP Exchange. (5 BP)
A23: =Source!$B$6 | B23: =Source!$S$17 | C23: =Source!$B$7 | D23: Incinium | F23: One Island's Pokémon Center, from the Battle Simulator BP Exchange. (5 BP)
A24: =Source!$B$6 | B24: =Source!$S$5 | C24: =Source!$B$7 | D24: Decidium | F24: One Island's Pokémon Center, from the Battle Simulator BP Exchange. (5 BP)
A25: =Source!$B$6 | B25: =Source!$S$28 | C25: =Source!$B$7 | D25: Primarium | F25: One Island's Pokémon Center, from the Battle Simulator BP Exchange. (5 BP)
A26: =Source!$B$6 | B26: =Source!$S$20 | C26: =Source!$B$7 | D26: Lycanium | F26: One Island's Pokémon Center, from the Battle Simulator BP Exchange. (25 BP)
A27: =Source!$B$6 | B27: =Source!$S$18 | C27: =Source!$B$7 | D27: Kommonium | F27: One Island's Pokémon Center, from the Battle Simulator BP Exchange. (25 BP)
A28: =Source!$B$6 | B28: =Source!$S$35 | C28: =Source!$B$7 | D28: Ultranecrozium | F28: One Island's Pokémon Center, from the Battle Simulator BP Exchange. (50 BP)

Sheet Shops
F6: CERULEAN CITY
F8: =Source!$D$13 | G8: TM 021 - Icy Wind | Y8: =Source!$B$8 | AA8: 5000
F10: =Source!$D$18 | G10: TM 047 - Steel Wing | Y10: =Source!$B$8 | AA10: 10 000
F12: =Source!$D$9 | G12: TM 087 - Aerial Ace | Y12: =Source!$B$8 | AA12: 5000
F14: =Source!$D$9 | G14: TM 088 - Pluck | Y14: =Source!$B$8 | AA14: 5000
F16: =Source!$D$3 | G16: TM 108 - Snarl | Y16: =Source!$B$8 | AA16: 5000
F18: =Source!$D$7 | G18: TM 111 - Vacuum Wave | Y18: =Source!$B$8 | AA18: 5000
F28: CELADON DEPT. STORE (2F)
F30: =Source!$Y$27 | G30: Net Ball | Y30: =Source!$B$8 | AA30: 1000
F32: =Source!$Y$4 | G32: Dive Ball | Y32: =Source!$B$8 | AA32: 1000
F34: =Source!$Y$26 | G34: Nest Ball | Y34: =Source!$B$8 | AA34: 1000
F36: =Source!$Y$33 | G36: Repeat Ball | Y36: =Source!$B$8 | AA36: 1000
F38: =Source!$Y$37 | G38: Timer Ball | Y38: =Source!$B$8 | AA38: 1000
F40: =Source!$Y$23 | G40: Luxury Ball | Y40: =Source!$B$8 | AA40: 1000
F42: =Source!$Y$32 | G42: Quick Ball | Y42: =Source!$B$8 | AA42: 1000
F44: =Source!$Y$6 | G44: Dusk Ball | Y44: =Source!$B$8 | AA44: 1000
F46: =Source!$Y$21 | G46: Love Ball | Y46: =Source!$B$8 | AA46: 1000
F48: =Source!$Y$7 | G48: Fast Ball | Y48: =Source!$B$8 | AA48: 1000
F50: =Source!$Y$20 | G50: Level Ball | Y50: =Source!$B$8 | AA50: 1000
F52: =Source!$Y$13 | G52: Heavy Ball | Y52: =Source!$B$8 | AA52: 1000
F54: =Source!$Y$25 | G54: Moon Ball | Y54: =Source!$B$8 | AA54: 1000
F64: CELADON DEPT. STORE (4F)
F66: =Source!$AK$13 | G66: Fire Stone | Y66: =Source!$B$8 | AA66: 3000
F68: =Source!$AK$38 | G68: Thunder Stone | Y68: =Source!$B$8 | AA68: 3000
F70: =Source!$AK$19 | G70: Leaf Stone | Y70: =Source!$B$8 | AA70: 3000
F72: =Source!$AK$40 | G72: Water Stone | Y72: =Source!$B$8 | AA72: 3000
F74: =Source!$AK$35 | G74: Sun Stone | Y74: =Source!$B$8 | AA74: 3000
F76: =Source!$AK$23 | G76: Moon Stone | Y76: =Source!$B$8 | AA76: 3000
F78: =Source!$AK$25 | G78: Prism Scale | Y78: =Source!$B$8 | AA78: 3000
F80: =Source!$AK$17 | G80: Ice Stone | Y80: =Source!$B$8 | AA80: 3000
F82: =IMAGE("https://i.ibb.co/jVdV50m/link.png",4,32,32) | G82: Link Cable | Y82: =Source!$B$8 | AA82: 2100
F84: =Source!$AK$11 | G84: Dusk Stone | Y84: =Source!$B$8 | AA84: 3000
F86: =Source!$AK$6 | G86: Dawn Stone | Y86: =Source!$B$8 | AA86: 3000
F88: =Source!$AK$32 | G88: Shiny Stone | Y88: =Source!$B$8 | AA88: 3000
F90: =Source!$AN$46 | G90: King's Rock | Y90: =Source!$B$8 | AA90: 5000
F92: =Source!$AN$58 | G92: Metal Coat | Y92: =Source!$B$8 | AA92: 3000
F102: CELADON DEPT. STORE (5F)
F104: =Source!$AB$22 | G104: HP Up | Y104: =Source!$B$8 | AA104: 10 000
F106: =Source!$AB$42 | G106: Protein | Y106: =Source!$B$8 | AA106: 10 000
F108: =Source!$AB$25 | G108: Iron | Y108: =Source!$B$8 | AA108: 10 000
...

Sheet Care Packages
E5: WHAT ARE CARE PACKAGES?
E6: At many points during your playthrough, you'll receive "Care Packages" that contain ALL items that you can grind/thief off Wild Pokémon and Raid Pokémon at the point you receive the Care Packages. At any point during your playthrough, you may go to the player's room in Pallet Town, and interact with the little game console near the TV. You'll be prompted to enter a code. Input "SO2Toxic". The codes are case-sensitive, so you should NOT try to input "so2toxic".
F14: (ITEMS HIGHLIGHTED IN RED ARE NOT GIVEN IN HARDCORE)
F15: (ITEMS HIGHLIGHTED IN BLUE ARE NOT GIVEN IN MGM + HARDCORE)
E19: ENTERING ROUTE 2
F21: =Source!$AN$2 | G21: Absorb Bulb [x10] | L21: =Source!$AT$4 | M21: Aspear Berry [x10] | R21: =Source!$AH$3 | S21: Big Mushroom [x10]
F24: =Source!$AE$32 | G24: Blue Shard [x10] | L24: =Source!$AT$8 | M24: Charti Berry [x10] | R24: =Source!$AT$11 | S24: Chilan Berry [x10]
F27: =Source!$AT$13 | G27: Coba Berry [x10] | L27: =Source!$AK$7 | M27: Deep Sea Scale [x10] | R27: =Source!$AK$8 | S27: Deep Sea Tooth [x10]
F30: =Source!$AE$33 | G30: Green Shard [x10] | L30: =Source!$AN$41 | M30: Hard Stone [x10] | R30: =Source!$AT$30 | S30: Kebia Berry [x10]
F33: =IMAGE("https://raw.githubusercontent.com/msikma/pokesprite/master/items/hold-item/light-ball.png",4,32,32) | G33: Light Ball [x10] | L33: =IMAGE("https://raw.githubusercontent.com/msikma/pokesprite/master/items/hold-item/mental-herb.png",4,32,32) | M33: Mental Herb [x10] | R33: =IMAGE("https://raw.githubusercontent.com/msikma/pokesprite/master/items/hold-item/mystic-water.png",4,32,32) | S33: Mystic Water [x10]
F36: =IMAGE("https://raw.githubusercontent.com/msikma/pokesprite/master/items/hold-item/never-melt-ice.png",4,32,32) | G36: Never-Melt Ice [x10] | L36: =Source!$AH$7 | M36: Nugget [x10] | R36: =Source!$AT$43 | S36: Occa Berry [x10]
F39: =Source!$AT$44 | G39: Oran Berry [x10] | L39: =Source!$AT$46 | M39: Passho Berry [x10] | R39: =Source!$AT$47 | S39: Payapa Berry [x10]
F42: =Source!$AT$48 | G42: Pecha Berry [x10] | L42: =IMAGE("https://raw.githubusercontent.com/msikma/pokesprite/master/items/plate/pixie.png",4,32,32) | M42: Pixie Plate [x10] | R42: =IMAGE("https://raw.githubusercontent.com/msikma/pokesprite/master/items/hold-item/poison-barb.png",4,32,32) | S42: Poison Barb [x10]
F45: =Source!$AB$39 | G45: Potion [x10] | L45: =Source!$AE$34 | M45: Red Shard [x10] | R45: =Source!$AB$47 | S45: Revive [x10]
F48: =Source!$AT$57 | G48: Rindo Berry [x10] | L48: =IMAGE("https://raw.githubusercontent.com/msikma/pokesprite/master/items/hold-item/sharp-beak.png",4,32,32) | M48: Sharp Beak [x10] | R48: =IMAGE("https://raw.githubusercontent.com/msikma/pokesprite/master/items/hold-item/silver-powder.png",4,32,32) | S48: Silver Powder [x10]
F51: =IMAGE("https://raw.githubusercontent.com/msikma/pokesprite/master/items/hold-item/soft-sand.png",4,32,32) | G51: Soft Sand [x10] | L51: =IMAGE("https://raw.githubusercontent.com/msikma/pokesprite/master/items/hold-item/spell-tag.png",4,32,32) | M51: Spell Tag [x10] | R51: =Source!$AH$24 | S51: Tiny Mushroom [x10]
F54: =IMAGE("https://raw.githubusercontent.com/msikma/pokesprite/master/items/hold-item/twisted-spoon.png",4,32,32) | G54: Twisted Spoon [x10] | L54: =Source!$AT$74 | M54: Yache Berry [x10] | R54: =Source!$Y$32 | S54: Quick Ball [x153]
F57: =IMAGE("https://raw.githubusercontent.com/msikma/pokesprite/master/items/hold-item/magnet.png",4,32,32) | G57: Magnet [x10] | L57: =IMAGE("https://raw.githubusercontent.com/msikma/pokesprite/master/items/hold-item/shell-bell.png",4,32,32) | M57: Shell Bell [x10] | R57: =IMAGE("https://raw.githubusercontent.com/msikma/pokesprite/master/items/hold-item/cleanse-tag.png",4,32,32) | S57: Cleanse Tag [x10]
E60: EXITING VIRIDIAN FOREST
F62: =Source!$AN$61 | G62: Miracle Seed [x10] | L62: =Source!$AT$69 | M62: Tanga Berry [x10] | R62: =Source!$AT$55 | S62: Rawst Berry [x10]
F65: =Source!$AT$49 | G65: Persim Berry [x10] | L65: =Source!$AN$27 | M65: Dragon Fang [x10] | R65: =Source!$AN$11 | S65: Black Glasses [x10]
F68: =Source!$AN$10 | G68: Black Belt [x10] | L68: =Source!$AN$69 | M68: Psychic Seed [x10]
E71: EXITING PEWTER CITY
F73: =Source!$AT$9 | G73: Cheri Berry [x10] | L73: =Source!$AT$12 | M73: Chople Berry [x10] | R73: =Source!$AK$23 | S73: Moon Stone [x10]
E76: ROUTE 3 AFTER LASS SALLY
F78: =Source!$AB$35 | G78: Muscle Wing [x10] | L78: =Source!$AB$42 | M78: Protein [x10] | R78: =Source!$AB$9 | S78: Carbos [x10]
F81: =Source!$AB$53 | G81: Swift Wing [x10] | L81: =Source!$AN$97 | M81: Throat Spray [x10] | R81: =Source!$AB$5 | S81: Berry Juice [x10]
F84: =Source!$AT$10 | G84: Chesto Berry [x10] | L84: =Source!$AB$15 | M84: Ether [x10] | R84: =Source!$Y$12 | S84: Heal Ball [x50]
F87: =Source!$AT$34 | G87: Leppa Berry [x10] | L87: =Source!$AN$52 | M87: Lucky Egg [x10] | R87: =Source!$AB$41 | S87: PP Up [x10]
F90: =Source!$AT$65 | G90: Sitrus Berry [x10] | L90: =Source!$AH$23 | M90: Stardust [x10] | R90: =Source!$AN$45 | S90: Iron Ball [x10]
E93: ROUTE 4 (EAST) AFTER EXITING MT. MOON
F95: =Source!$AB$9 | G95: Carbos [x10] | L95: =Source!$AB$53 | M95: Swift Wing [x10] | R95: =Source!$AB$8 | S95: Calcium [x10]
F98: =Source!$AB$19 | G98: Genius Wing [x10] | L98: =Source!$AN$42 | M98: Heat Rock [x10] | R98: =Source!$AH$22 | S98: Star Piece [x10]
F101: =Source!$AT$14 | G101: Colbur Berry [x10] | L101: =Source!$AN$103 | M101: Wide Lens [x10]
E104: NUGGET BRIDGE AFTER DEFEATING GRUNT
F106: =Source!$AB$21 | G106: Health Wing [x10] | L106: =Source!$AB$22 | M106: HP Up [x10] | R106: =Source!$CD$14 | S106: Leek Stick [x10]
F109: =Source!$AN$85 | G109: Silk Scarf [x10] | L109: =Source!$AT$70 | M109: Wacan Berry [x10]
E112: CERULEAN CITY AFTER DEFEATING GRUNT
F114: =Source!$AB$2 | G114: Ability Pill [x306] | L114: =Source!$AH$5 | M114: Big Pearl [x10] | R114: =Source!$AN$18 | S114: Charcoal [x10]
F117: =Source!$AT$25 | G117: Haban Berry [x10] | L117: =Source!$AH$8 | M117: Pearl [x10] | R117: =Source!$Y$38 | S117: Ultra Ball [x10]
...

Sheet Other Useful Items
C3: SHARDS - Used for obtaining Starter Eggs, Pikachu forms and fossils.
C4: =Source!$AE$33 | D4: GREEN SHARD | E4: =IMAGE("https://i.ibb.co/SXG0s7n/2-1.png") | H4: =Source!$AE$32 | I4: BLUE SHARD | J4: =IMAGE("https://i.ibb.co/Kx0DJFL/2-1.png") | M4: =Source!$AE$34 | N4: RED SHARD | O4: =IMAGE("https://i.ibb.co/MBxgmgC/2-1.png") | R4: =Source!$AE$35 | S4: YELLOW SHARD | T4: =IMAGE("https://i.ibb.co/yR6q8VR/2-1.png")
C5: =IMAGE("https://i.ibb.co/Kh4gzYd/bellsprout.png",3) | D5: Bellsprout | E5: =IMAGE("https://i.ibb.co/SXG0s7n/2-1.png") | H5: =IMAGE("https://i.ibb.co/23Zt61m/psyduck.png",3) | I5: Psyduck | J5: =IMAGE("https://i.ibb.co/Kx0DJFL/2-1.png") | M5: =IMAGE("https://i.ibb.co/fFLZdT1/slugma.png",3) | N5: Slugma | O5: =IMAGE("https://i.ibb.co/MBxgmgC/2-1.png") | R5: =IMAGE("https://i.ibb.co/1R0GVXQ/elektrike.png",3) | S5: Electrike | T5: =IMAGE("https://i.ibb.co/yR6q8VR/2-1.png")
C6: =IMAGE("https://i.ibb.co/k01WJ5W/weepinbell.png",3) | D6: Weepinbell | E6: =IMAGE("https://i.ibb.co/SXG0s7n/2-1.png") | H6: =IMAGE("https://i.ibb.co/crmqJLK/Golduck.png",3) | I6: Golduck | J6: =IMAGE("https://i.ibb.co/Kx0DJFL/2-1.png") | M6: =IMAGE("https://i.ibb.co/1L992Td/Magcargo.png",3) | N6: Magcargo | O6: =IMAGE("https://i.ibb.co/MBxgmgC/2-1.png") | R6: =IMAGE("https://i.ibb.co/F0pG6Yy/manectric.png",3) | S6: Manectric | T6: =IMAGE("https://i.ibb.co/yR6q8VR/2-1.png")
C7: =IMAGE("https://i.ibb.co/yyyPt1r/Victreebel.png",3) | D7: Victreebel | E7: =IMAGE("https://i.ibb.co/SXG0s7n/2-1.png") | M7: =IMAGE("https://i.ibb.co/zNYnWt1/hondour.png",3) | N7: Houndour | O7: =IMAGE("https://i.ibb.co/MBxgmgC/2-1.png") | R7: =IMAGE("https://i.ibb.co/nf5Fjth/helioptile.png",3) | S7: Helioptile | T7: =IMAGE("https://i.ibb.co/yR6q8VR/2-1.png")
C8: =IMAGE("https://i.ibb.co/9VdMQVC/cherubi.png",3) | D8: Cherubi | E8: =IMAGE("https://i.ibb.co/SXG0s7n/2-1.png") | M8: =IMAGE("https://i.ibb.co/KxHgh8J/Houndoom.png",3) | N8: Houndoom | O8: =IMAGE("https://i.ibb.co/MBxgmgC/2-1.png") | R8: =IMAGE("https://i.ibb.co/LhmDHkz/heliolisk.png",3) | S8: Heliolisk | T8: =IMAGE("https://i.ibb.co/yR6q8VR/2-1.png")
C9: =IMAGE("https://i.ibb.co/tpCgqPp/cherrim.png",3) | D9: Cherrim | E9: =IMAGE("https://i.ibb.co/SXG0s7n/2-1.png") | M9: =IMAGE("https://i.ibb.co/x6qRNSV/litleo.png",3) | N9: Litleo | O9: =IMAGE("https://i.ibb.co/MBxgmgC/2-1.png")
M10: =IMAGE("https://i.ibb.co/jg5kX6t/Pyroar.png",3) | N10: Pyroar | O10: =IMAGE("https://i.ibb.co/MBxgmgC/2-1.png")
C12: LUCKY EGGS - Unobtainable from Pelipper in Hardcore.
C13: =Source!$AN$52 | D13: LUCKY EGG | E13: =IMAGE("https://i.ibb.co/QbW3HFJ/2-1.png")
C14: =IMAGE("https://i.ibb.co/748TmNL/chansey.png",3) | D14: Chansey | E14: =IMAGE("https://i.ibb.co/QbW3HFJ/2-1.png")
C15: =IMAGE("https://i.ibb.co/g4t2yGS/blissey.png",3) | D15: Blissey | E15: =IMAGE("https://i.ibb.co/QbW3HFJ/2-1.png")
C16: =IMAGE("https://i.ibb.co/PTX895c/pelipper.png",3) | D16: Pelipper | E16: =IMAGE("https://i.ibb.co/QbW3HFJ/2-1.png")
C18: NUGGETS -Sell for money.
C19: =Source!$AH$7 | D19: NUGGET | E19: =IMAGE("https://i.ibb.co/LNKxQy5/2-1.png") | H19: =Source!$AH$4 | I19: BIG NUGGET | J19: =IMAGE("https://i.ibb.co/LNKxQy5/2-1.png")
C20: =IMAGE("https://i.ibb.co/P1stQMW/meowth.png",3) | D20: Meowth | E20: =IMAGE("https://i.ibb.co/LNKxQy5/2-1.png") | H20: =IMAGE("https://i.ibb.co/C2TBQzg/Persian.png",3) | I20: Persian | J20: =IMAGE("https://i.ibb.co/LNKxQy5/2-1.png")
C21: =IMAGE("https://i.ibb.co/1Mt9F16/meowthalola.png",3) | D21: Meowth-Alola | E21: =IMAGE("https://i.ibb.co/LNKxQy5/2-1.png") | H21: =IMAGE("https://i.ibb.co/zZbC8Yj/pers.png",3) | I21: Persian-Alola | J21: =IMAGE("https://i.ibb.co/LNKxQy5/2-1.png")
C23: WISHING PIECES - Commonly found in raid dens.
C24: =Source!$AE$30 | D24: WISHING PIECE | E24: =IMAGE("https://i.ibb.co/kqzX8TK/2-1.png")
C26: AIR BALLOONS - Unobtainable in Hardcore.
C27: =Source!$AN$5 | D27: AIR BALLOON | E27: =IMAGE("https://i.ibb.co/MBxgmgC/2-1.png")
C28: =IMAGE("https://i.ibb.co/2srNqQz/drifloon.png",3) | D28: Drifloon | E28: =IMAGE("https://i.ibb.co/MBxgmgC/2-1.png")
C29: =IMAGE("https://i.ibb.co/b7PS0Dk/Drifblim.png",3) | D29: Drifblim | E29: =IMAGE("https://i.ibb.co/MBxgmgC/2-1.png")
C31: WEATHER ROCKS - All unobtainable in Hardcore.
C32: =Source!$AN$24 | D32: DAMP ROCK | E32: =IMAGE("https://i.ibb.co/RDzHWPM/2-1.png") | H32: =Source!$AN$42 | I32: HEAT ROCK | J32: =IMAGE("https://i.ibb.co/MBxgmgC/2-1.png") | M32: =Source!$AN$44 | N32: ICY ROCK | O32: =IMAGE("https://i.ibb.co/GfS66RX/2-1.png") | R32: =Source!$AN$88 | S32: SMOOTH ROCK | T32: =IMAGE("https://i.ibb.co/ysHMCF9/2-1.png")
C33: =IMAGE("https://i.ibb.co/PTX895c/pelipper.png",3) | D33: Pelipper | E33: =IMAGE("https://i.ibb.co/RDzHWPM/2-1.png") | H33: =IMAGE("https://i.ibb.co/5G3ZV3q/Ninetales.png",3) | I33: Ninetales | J33: =IMAGE("https://i.ibb.co/MBxgmgC/2-1.png") | M33: =IMAGE("https://i.ibb.co/0jFH5pX/Abomasnow.png",3) | N33: Abomasnow | O33: =IMAGE("https://i.ibb.co/GfS66RX/2-1.png") | R33: =IMAGE("https://i.ibb.co/Jvr5BMW/Hippowdon.png",3) | S33: Hippowdon | T33: =IMAGE("https://i.ibb.co/ysHMCF9/2-1.png")
C34: =IMAGE("https://i.ibb.co/6Z89qvb/Politoed.png",3) | D34: Politoed | E34: =IMAGE("https://i.ibb.co/RDzHWPM/2-1.png") | H34: =IMAGE("https://i.ibb.co/L9YKsL2/Torkoal.png",3) | I34: Torkoal | J34: =IMAGE("https://i.ibb.co/MBxgmgC/2-1.png") | M34: =IMAGE("https://i.ibb.co/jkYSpwc/Alolatales.png",3) | N34: Ninetales-Alola | O34: =IMAGE("https://i.ibb.co/GfS66RX/2-1.png")
C36: WEAKNESS POLICYS - Unobtainable in Hardcore.
C37: =Source!$AN$101 | D37: WEAKNESS POL. | E37: =IMAGE("https://i.ibb.co/g7VX0Py/2-1.png")
C38: =IMAGE("https://i.ibb.co/VD5ScsN/graveler.png",3) | D38: Graveler | E38: =IMAGE("https://i.ibb.co/g7VX0Py/2-1.png")
C39: =IMAGE("https://i.ibb.co/n7Q6nDv/graveleralola.png",3) | D39: Graveler-Alola | E39: =IMAGE("https://i.ibb.co/g7VX0Py/2-1.png")
C40: =IMAGE("https://i.ibb.co/z5vjSp0/Golem.png",3) | D40: Golem | E40: =IMAGE("https://i.ibb.co/g7VX0Py/2-1.png")
C41: =IMAGE("https://i.ibb.co/YTndySc/GolemA.png",3) | D41: Golem-Alola | E41: =IMAGE("https://i.ibb.co/g7VX0Py/2-1.png")
C43: TERRAIN SEEDS
C44: =Source!$AN$38 | D44: GRASSY SEED | E44: =IMAGE("https://i.ibb.co/SXG0s7n/2-1.png") | H44: =Source!$AN$62 | I44: MISTY SEED | J44: =IMAGE("https://i.ibb.co/T1JMdL3/2-1.png") | M44: =Source!$AN$69 | N44: PSYCHIC SEED | O44: =IMAGE("https://i.ibb.co/Khzxsvn/2-1.png") | R44: =Source!$AN$30 | S44: ELECTRIC SEED | T44: =IMAGE("https://i.ibb.co/yR6q8VR/2-1.png")
C45: =IMAGE("https://i.ibb.co/N3RPVYD/Tsareena.png",3) | D45: Tsareena | E45: =IMAGE("https://i.ibb.co/SXG0s7n/2-1.png") | H45: =IMAGE("https://i.ibb.co/qsqsS6r/comfey.png",3) | I45: Comfey | J45: =IMAGE("https://i.ibb.co/T1JMdL3/2-1.png") | M45: =IMAGE("https://i.ibb.co/9WrM5n8/exeggcute.png",3) | N45: Exeggcute | O45: =IMAGE("https://i.ibb.co/Khzxsvn/2-1.png") | R45: =IMAGE("https://i.ibb.co/F7d9rWB/togedemaru.png",3) | S45: Togedemaru | T45: =IMAGE("https://i.ibb.co/yR6q8VR/2-1.png")

Sheet Source
B2: =IMAGE("https://i.ibb.co/GJGBQ1p/1.png") | D2: =IMAGE("https://raw.githubusercontent.com/msikma/pokesprite/master/items/tm/bug.png",4,32,32) | E2: Bug | G2: {=IMAGE("https://raw.githubusercontent.com/msikma/pokesprite/master/items/memory/"&H2:H229&".png",4,32,32)} | H2: bug | J2: {=IMAGE("https://raw.githubusercontent.com/msikma/pokesprite/master/items/tr/"&K2:K229&".png",4,32,32)} | K2: bug | M2: {=IMAGE("https://raw.githubusercontent.com/msikma/pokesprite/master/items/gem/"&N2:N229&".png",4,32,32)} | N2: bug | P2: {=IMAGE("https://raw.githubusercontent.com/msikma/pokesprite/master/items/mega-stone/"&Q2:Q229&".png",4,32,32)} | Q2: abomasite | S2: {=IMAGE("https://raw.githubusercontent.com/msikma/pokesprite/master/items/z-crystals/"&T2:T229&".png",4,32,32)} | T2: aloraichium-z--held | V2: =IMAGE("https://i.ibb.co/jzCSPJ0/Screenshot-1.png") | W2: Bug Catcher | Y2: {=IMAGE("https://raw.githubusercontent.com/msikma/pokesprite/master/items/ball/"&Z2:Z229&".png",4,32,32)} | Z2: beast | AB2: {=IMAGE("https://raw.githubusercontent.com/msikma/pokesprite/master/items/medicine/"&AC2:AC229&".png",4,32,32)} | AC2: ability-capsule | AE2: {=IMAGE("https://raw.githubusercontent.com/msikma/pokesprite/master/items/other-item/"&AF2:AF31&".png",4,32,32)} | AF2: ability-patch | AH2: {=IMAGE("https://raw.githubusercontent.com/msikma/pokesprite/master/items/valuable-item/"&AI2:AI229&".png",4,32,32)} | AI2: balm-mushroom | AK2: {=IMAGE("https://raw.githubusercontent.com/msikma/pokesprite/master/items/evo-item/"&AL2:AL229&".png",4,32,32)} | AL2: berry-sweet | AN2: {=IMAGE("https://raw.githubusercontent.com/msikma/pokesprite/master/items/hold-item/"&AO2:AO229&".png",4,32,32)} | AO2: absorb-bulb | AQ2: {=IMAGE("https://raw.githubusercontent.com/msikma/pokesprite/master/items/key-item/"&AR2:AR229&".png",4,32,32)} | AR2: acro-bike | AT2: {=IMAGE("https://raw.githubusercontent.com/msikma/pokesprite/master/items/berry/"&AU2:AU229&".png",4,32,32)} | AU2: aguav | AW2: {=IMAGE("https://raw.githubusercontent.com/msikma/pokesprite/master/items/mail/"&AX2:AX229&".png",4,32,32)} | AX2: air-mail | AZ2: {=IMAGE("https://raw.githubusercontent.com/msikma/pokesprite/master/items/battle-item/"&BA2:BA229&".png",4,32,32)} | BA2: dire-hit | BC2: {=IMAGE("https://raw.githubusercontent.com/msikma/pokesprite/master/items/flute/"&BD2:BD229&".png",4,32,32)} | BD2: black | BF2: {=IMAGE("https://raw.githubusercontent.com/msikma/pokesprite/master/items/mulch/"&BG2:BG229&".png",4,32,32)} | BG2: amaze | BI2: {=IMAGE("https://raw.githubusercontent.com/msikma/pokesprite/master/items/fossil/"&BJ2:BJ229&".png",4,32,32)} | BJ2: armor | BL2: {=IMAGE("https://raw.githubusercontent.com/msikma/pokesprite/master/items/ev-item/"&BM2:BM229&".png",4,32,32)} | BM2: macho-brace | BO2: {=IMAGE("https://raw.githubusercontent.com/msikma/pokesprite/master/items/incense/"&BP2:BP229&".png",4,32,32)} | BP2: full | BR2: {=IMAGE("https://raw.githubusercontent.com/msikma/pokesprite/master/items/plate/"&BS2:BS229&".png",4,32,32)} | BS2: draco | BU2: {=IMAGE("https://raw.githubusercontent.com/msikma/pokesprite/master/items/apricorn/"&BV2:BV229&".png",4,32,32)} | BV2: black | BX2: {=IMAGE("https://raw.githubusercontent.com/msikma/pokesprite/master/items/partner-gift/"&BY2:BY229&".png",4,32,32)} | BY2: beach-glass | CA2: {=IMAGE("https://raw.githubusercontent.com/msikma/pokesprite/master/items/petal/"&CB2:CB229&".png",4,32,32)} | CB2: blue | CD2: {=IMAGE("https://raw.githubusercontent.com/msikma/pokesprite/master/items/curry-ingredient/"&CE2:CE229&".png",4,32,32)} | CE2: bachs-food-tin | CG2: {=IMAGE("https://raw.githubusercontent.com/msikma/pokesprite/master/items/exp-candy/"&CH2:CH229&".png",4,32,32)} | CH2: l | CJ2: {=IMAGE("https://raw.githubusercontent.com/msikma/pokesprite/master/items/mint/"&CK2:CK229&".png",4,32,32)} | CK2: attack
B3: =IMAGE("https://i.ibb.co/0VkqLZf/2.png") | D3: =IMAGE("https://raw.githubusercontent.com/msikma/pokesprite/master/items/tm/dark.png",4,32,32) | E3: Dark | H3: dark | K3: dark | N3: dark | Q3: absolite | T3: buginium-z--held | V3: =IMAGE("https://i.ibb.co/K5Xv1gX/oldman.png") | W3: Old Man | Z3: cherish | AC3: antidote | AF3: armorite-ore | AI3: big-mushroom | AL3: chipped-pot | AO3: adamant-orb | AR3: adventure-guide | AU3: apicot | AX3: bead-mail | BA3: guard-spec | BD3: blue | BG3: boost | BJ3: bird | BM3: power-anklet | BP3: lax | BS3: dread | BV3: blue | BY3: chalky-stone | CB3: green | CE3: bobs-food-tin | CH3: m | CK3: defense
B4: =IMAGE("https://i.ibb.co/Wt7tqk6/Screenshot-2.png",4,15,15) | D4: =IMAGE("https://raw.githubusercontent.com/msikma/pokesprite/master/items/tm/dragon.png",4,32,32) | E4: Dragon | H4: dragon | K4: dragon | N4: dragon | Q4: aerodactylite | T4: darkinium-z--held | V4: =IMAGE("https://i.ibb.co/RNTZKct/Screenshot-4.png") | W4: Tamer | Z4: dive | AC4: awakening | AF4: bottle-cap | AI4: big-nugget | AL4: clover-sweet | AO4: adrenaline-orb | AR4: apricorn-box | AU4: aspear | AX4: bloom-mail | BA4: max-mushrooms | BD4: red | BG4: damp | BJ4: claw | BM4: power-band | BP4: luck | BS4: earth | BV4: green | BY4: gold-leaf | CB4: orange | CE4: boiled-egg | CH4: s | CK4: neutral
B5: =IMAGE("https://i.ibb.co/Wt7tqk6/Screenshot-2.png",4,15,15) | D5: =IMAGE("https://raw.githubusercontent.com/msikma/pokesprite/master/items/tm/electric.png",4,32,32) | E5: Electric | H5: electric | K5: electric | N5: electric | Q5: aggronite | T5: decidium-z--held | V5: =IMAGE("https://i.ibb.co/JrCg1n0/ace.png") | W5: Ace Trainer | Z5: dream | AC5: berry-juice | AF5: discount-coupon | AI5: big-pearl | AL5: cracked-pot | AO5: air-balloon | AR5: aqua-suit | AU5: babiri | AX5: brick-mail | BA5: x-accuracy | BD5: white | BG5: gooey | BJ5: cover | BM5: power-belt | BP5: odd | BS5: fist | BV5: pink | BY5: leaf-letter-eevee | CB5: pink | CE5: bread | CH5: xl | CK5: special-attack
B6: =IMAGE("https://i.ibb.co/9t4FGkb/left.png") | D6: =IMAGE("https://raw.githubusercontent.com/msikma/pokesprite/master/items/tm/fairy.png",4,32,32) | E6: Fairy | H6: fairy | K6: fairy | N6: fairy | Q6: alakazite | T6: dragonium-z--held | V6: =IMAGE("https://i.ibb.co/QHv5Kn4/Screenshot-1.png") | W6: Super Nerd | Z6: dusk | AC6: big-malasada | AF6: dynamax-candy | AI6: comet-shard | AL6: dawn-stone | AO6: amulet-coin | AR6: armor-pass | AU6: belue | AX6: bridge-mail-d | BA6: x-attack | BD6: yellow | BG6: growth | BJ6: dino | BM6: power-bracer | BP6: pure | BS6: flame | BV6: red | BY6: leaf-letter-pikachu | CB6: purple | CE6: brittle-bones | CH6: xs | CK6: special-defense
B7: =IMAGE("https://i.ibb.co/9sSLT6b/right.png") | D7: =IMAGE("https://raw.githubusercontent.com/msikma/pokesprite/master/items/tm/fighting.png",4,32,32) | E7: Fighting | H7: fighting | K7: fighting | N7: fighting | Q7: altarianite | T7: eevium-z--held | V7: =IMAGE("https://i.ibb.co/Jqr38wc/Screenshot-2.png") | W7: Bug Catcher 2 | Z7: fast | AC7: burn-heal | AF7: dynamax-crystal | AI7: nugget | AL7: deep-sea-scale | AO7: assault-vest | AR7: auroraticket | AU7: bluk | AX7: bridge-mail-m | BA7: x-defense | BG7: rich | BJ7: dome | BM7: power-lens | BP7: rock | BS7: icicle | BV7: white | BY7: lone-earring | CB7: red | CE7: coconut-milk | CK7: speed
B8: =IMAGE("https://i.ibb.co/6410MSY/money.png") | D8: =IMAGE("https://raw.githubusercontent.com/msikma/pokesprite/master/items/tm/fire.png",4,32,32) | E8: Fire | H8: fire | K8: fire | N8: fire | Q8: ampharosite | T8: electrium-z--held | V8: =IMAGE("https://i.ibb.co/rGcwQTb/Screenshot-3.png") | W8: Super Nerd 2 | Z8: feather | AC8: calcium | AF8: dynite-ore | AI8: pearl | AL8: deep-sea-tooth | AO8: big-root | AR8: autograph | AU8: charti | AX8: bridge-mail-s | BA8: x-sp-atk | BG8: stable | BJ8: drake | BM8: power-weight | BP8: rose | BS8: insect | BV8: yellow | BY8: marble | CB8: yellow | CE8: fancy-apple
D9: =IMAGE("https://raw.githubusercontent.com/msikma/pokesprite/master/items/tm/flying.png",4,32,32) | E9: Flying | H9: flying | K9: flying | N9: flying | Q9: audinite | T9: fairium-z--held | V9: =IMAGE("https://i.ibb.co/djd6Zbm/Screenshot-4.png") | W9: Super Nerd 3 | Z9: friend | AC9: carbos | AF9: escape-rope | AI9: pearl-string | AL9: dragon-scale | AO9: binding-band | AR9: azure-flute | AU9: cheri | AX9: bridge-mail-t | BA9: x-sp-def | BG9: surprise | BJ9: fish | BP9: sea | BS9: iron | BY9: polished-mud-ball | CE9: fresh-cream
D10: =IMAGE("https://raw.githubusercontent.com/msikma/pokesprite/master/items/tm/ghost.png",4,32,32) | E10: Ghost | H10: ghost | K10: ghost | N10: ghost | Q10: banettite | T10: fightinium-z--held | V10: =IMAGE("https://i.ibb.co/8cwjJ93/Screenshot-5.png") | W10: Ace Trainer 2 | Z10: gigaton | AC10: casteliacone | AF10: fluffy-tail | AI10: pretty-wing | AL10: dubious-disc | AO10: black-belt | AR10: band-autograph | AU10: chesto | AX10: bridge-mail-v | BA10: x-speed | BJ10: helix | BP10: wave | BS10: meadow | BY10: silver-leaf | CE10: fried-food
D11: =IMAGE("https://raw.githubusercontent.com/msikma/pokesprite/master/items/tm/grass.png",4,32,32) | E11: Grass | H11: grass | K11: grass | N11: grass | Q11: beedrillite | T11: firium-z--held | V11: =IMAGE("https://i.ibb.co/fpwCDs8/Screenshot-6.png") | W11: Mom | Z11: great | AC11: clever-wing | AF11: galarica-twig | AI11: rare-bone | AL11: dusk-stone | AO11: black-glasses | AR11: basement-key | AU11: chilan | AX11: bubble-mail | BJ11: jaw | BS11: mind | BY11: small-bouquet | CE11: fruit-bunch
D12: =IMAGE("https://raw.githubusercontent.com/msikma/pokesprite/master/items/tm/ground.png",4,32,32) | E12: Ground | H12: ground | K12: ground | N12: ground | Q12: blastoisinite | T12: flyinium-z--held | V12: =IMAGE("https://i.ibb.co/94N2sVx/rachel.png") | W12: Rachel | Z12: heal | AC12: elixir | AF12: gold-bottle-cap | AI12: relic-band | AL12: electirizer | AO12: black-sludge | AR12: basement-key--goldenrod | AU12: chople | AX12: dream-mail | BJ12: old-amber | BS12: pixie | BY12: stretchy-spring | CE12: gigantamix
D13: =IMAGE("https://raw.githubusercontent.com/msikma/pokesprite/master/items/tm/ice.png",4,32,32) | E13: Ice | H13: ice | K13: ice | N13: ice | Q13: blazikenite | T13: ghostium-z--held | V13: =IMAGE("https://i.ibb.co/DV854sM/Screenshot-1.png") | W13: Ace Trainer 3 | Z13: heavy | AC13: energy-powder | AF13: heart-scale | AI13: relic-copper | AL13: fire-stone | AO13: blue-orb | AR13: basement-key--new-mauville | AU13: coba | AX13: fab-mail | BJ13: plume | BS13: sky | BY13: tropical-shell | CE13: instant-noodles
D14: =IMAGE("https://raw.githubusercontent.com/msikma/pokesprite/master/items/tm/normal.png",4,32,32) | E14: Normal | H14: poison | K14: normal | N14: normal | Q14: cameruptite | T14: grassium-z--held | V14: =IMAGE("https://i.ibb.co/x1ZJhDZ/maniac.png") | W14: Pokémaniac | Z14: hisuian-great | AC14: energy-root | AF14: honey | AI14: relic-crown | AL14: flower-sweet | AO14: blunder-policy | AR14: berry-pots | AU14: colbur | AX14: favored-mail | BJ14: root | BS14: splash | CE14: large-leek
D15: =IMAGE("https://raw.githubusercontent.com/msikma/pokesprite/master/items/tm/poison.png",4,32,32) | E15: Poison | H15: psychic | K15: poison | N15: poison | Q15: charizardite-x | T15: groundium-z--held | V15: =IMAGE("https://i.ibb.co/yq8TYD9/oldman.png") | W15: Old Man 2 | Z15: hisuian-heavy | AC15: ether | AF15: lure | AI15: relic-gold | AL15: galarica-cuff | AO15: bright-powder | AR15: berry-pouch | AU15: cornn | AX15: flame-mail | BJ15: sail | BS15: spooky | CE15: mixed-mushrooms
D16: =IMAGE("https://raw.githubusercontent.com/msikma/pokesprite/master/items/tm/psychic.png",4,32,32) | E16: Psychic | H16: rock | K16: psychic | N16: psychic | Q16: charizardite-y | T16: icium-z--held | V16: =IMAGE("https://i.ibb.co/NNgpZtp/tamer.png") | W16: Tamer 2 | Z16: hisuian-poke | AC16: fresh-water | AF16: max-lure | AI16: relic-silver | AL16: galarica-wreath | AO16: burn-drive | AR16: bicycle | AU16: custap | AX16: glitter-mail | BJ16: skull | BS16: stone | CE16: moomoo-cheese
D17: =IMAGE("https://raw.githubusercontent.com/msikma/pokesprite/master/items/tm/rock.png",4,32,32) | E17: Rock | H17: steel | K17: rock | N17: rock | Q17: diancite | T17: incinium-z--held | V17: =IMAGE("https://i.ibb.co/QQfMnKS/Screenshot-1.png") | W17: Scientist | Z17: hisuian-ultra | AC17: full-heal | AF17: max-repel | AI17: relic-statue | AL17: ice-stone | AO17: cell-battery | AR17: bike--green | AU17: durin | AX17: grass-mail | BS17: toxic | CE17: pack-of-potatoes
D18: =IMAGE("https://raw.githubusercontent.com/msikma/pokesprite/master/items/tm/steel.png",4,32,32) | E18: Steel | H18: water | K18: steel | N18: steel | Q18: galladite | T18: kommonium-z--held | Z18: jet | AC18: full-restore | AF18: odd-keystone | AI18: relic-vase | AL18: kings-rock | AO18: charcoal | AR18: bike--green | AU18: enigma | AX18: greet-mail | BS18: zap | CE18: packaged-curry
D19: =IMAGE("https://raw.githubusercontent.com/msikma/pokesprite/master/items/tm/water.png",4,32,32) | E19: Water | K19: water | N19: water | Q19: garchompite | T19: lunalium-z--held | Z19: leaden | AC19: genius-wing | AF19: pass-orb | AI19: shoal-salt | AL19: leaf-stone | AO19: chill-drive | AR19: bike--yellow | AU19: figy | AX19: harbor-mail | CE19: pasta
Q20: gardevoirite | T20: lycanium-z--held | Z20: level | AC20: heal-powder | AF20: pink-nectar | AI20: shoal-shell | AL20: love-sweet | AO20: choice-band | AR20: bike-voucher | AU20: ganlon | AX20: heart-mail | CE20: precooked-burger
Q21: gengarite | T21: marshadium-z--held | Z21: love | AC21: health-wing | AF21: poke-doll | AI21: slowpoke-tail | AL21: magmarizer | AO21: choice-scarf | AR21: black-mane-hair | AU21: golden-nanab | AX21: inquiry-mail | CE21: pungent-root
Q22: glalitite | T22: mewnium-z--held | Z22: lure | AC22: hp-up | AF22: poke-toy | AI22: star-piece | AL22: metal-coat | AO22: choice-specs | AR22: blue-card | AU22: golden-pinap | AX22: like-mail | CE22: salad-mix
Q23: gyaradosite | T23: mimikium-z--held | Z23: luxury | AC23: hyper-potion | AF23: purple-nectar | AI23: stardust | AL23: moon-stone | AO23: cleanse-tag | AR23: camping-gear | AU23: golden-razz | AX23: mech-mail | CE23: sausages
Q24: heracronite | T24: normalium-z--held | Z24: master | AC24: ice-heal | AF24: red-nectar | AI24: tiny-mushroom | AL24: oval-stone | AO24: damp-rock | AR24: card-key | AU24: grepa | AX24: mosaic-mail | CE24: smoke-poke-tail
Q25: houndoominite | T25: pikanium-z--held | Z25: moon | AC25: iron | AF25: repel | AL25: prism-scale | AO25: destiny-knot | AR25: carrot-seeds | AU25: haban | AX25: orange-mail | CE25: spice-mix
Q26: kangaskhanite | T26: pikashunium-z--held | Z26: nest | AC26: lava-cookie | AF26: soothe-bell | AL26: protector | AO26: douse-drive | AR26: catching-charm | AU26: hondew | AX26: reply-mail | CE26: tin-of-beans
Q27: latiasite | T27: poisonium-z--held | Z27: net | AC27: lemonade | AF27: strange-souvenir | AL27: razor-claw | AO27: dragon-fang | AR27: clear-bell | AU27: iapapa | AX27: retro-mail
Q28: latiosite | T28: primarium-z--held | Z28: origin | AC28: lumiose-galette | AF28: super-lure | AL28: razor-fang | AO28: eject-button | AR28: coin-case | AU28: jaboca | AX28: rsvp-mail
Q29: lopunnite | T29: psychium-z--held | Z29: park | AC29: max-elixir | AF29: super-repel | AL29: reaper-cloth | AO29: eject-pack | AR29: colress-machine | AU29: kasib | AX29: shadow-mail
Q30: lucarionite | T30: rockium-z--held | Z30: poke | AC30: max-ether | AF30: wishing-piece | AL30: ribbon-sweet | AO30: electric-seed | AR30: common-stone | AU30: kebia | AX30: snow-mail
Q31: manectite | T31: snorlium-z--held | Z31: premier | AC31: max-honey | AF31: yellow-nectar | AL31: sachet | AO31: everstone | AR31: contest-costume--dress | AU31: kee | AX31: space-mail
Q32: mawilite | T32: solganium-z--held | Z32: quick | AC32: max-potion | AE32: =IMAGE("https://raw.githubusercontent.com/msikma/pokesprite/master/items/shard/blue.png",4,32,32) | AF32: blue | AL32: shiny-stone | AO32: eviolite | AR32: contest-costume--jacket | AU32: kelpsy | AX32: steel-mail
Q33: medichamite | T33: steelium-z--held | Z33: repeat | AC33: max-revive | AE33: =IMAGE("https://raw.githubusercontent.com/msikma/pokesprite/master/items/shard/green.png",4,32,32) | AF33: green | AL33: star-sweet | AO33: expert-belt | AR33: contest-pass | AU33: lansat | AX33: thanks-mail
Q34: metagrossite | T34: tapunium-z--held | Z34: safari | AC34: moomoo-milk | AE34: =IMAGE("https://raw.githubusercontent.com/msikma/pokesprite/master/items/shard/red.png",4,32,32) | AF34: red | AL34: strawberry-sweet | AO34: flame-orb | AR34: coupon-1 | AU34: leppa | AX34: tropic-mail
Q35: mewtwonite-x | T35: ultranecrozium-z--held | Z35: sport | AC35: muscle-wing | AE35: =IMAGE("https://raw.githubusercontent.com/msikma/pokesprite/master/items/shard/yellow.png",4,32,32) | AF35: yellow | AL35: sun-stone | AO35: float-stone | AR35: coupon-2 | AU35: liechi | AX35: tunnel-mail
Q36: mewtwonite-y | T36: waterium-z--held | Z36: strange | AC36: old-gateau | AL36: sweet-apple | AO36: focus-band | AR36: coupon-3 | AU36: lum | AX36: wave-mail
Q37: pidgeotite | Z37: timer | AC37: paralyze-heal | AL37: tart-apple | AO37: focus-sash | AR37: crown-pass | AU37: mago | AX37: wood-mail
Q38: pinsirite | Z38: ultra | AC38: pewter-crunchies | AL38: thunder-stone | AO38: grassy-seed | AR38: dark-stone | AU38: magost
Q39: sablenite | Z39: wing | AC39: potion | AL39: up-grade | AO39: grip-claw | AR39: data-card | AU39: maranga
Q40: salamencite | AC40: pp-max | AL40: water-stone | AO40: griseous-orb | AR40: devon-goods | AU40: micle
Q41: sceptilite | AC41: pp-up | AL41: whipped-dream | AO41: hard-stone | AR41: devon-parts | AU41: nanab
...
